<?xml version="1.0" ?>
<!-- =================================================================================== -->
<!-- |    This document was autogenerated by xacro from /home/trgtulas/limo_ws/src/limo_cobot_sim/limo_mycobot/limo/limo_description/urdf/limo_four_diff_with_arm.xacro | -->
<!-- |    EDITING THIS FILE BY HAND IS NOT RECOMMENDED                                 | -->
<!-- =================================================================================== -->
<robot name="limo_mycobot">
    <transmission name="joint1_trans">
        <type>transmission_interface/SimpleTransmission</type>
        <joint name="joint2_to_joint1">
            <hardwareInterface>hardware_interface/EffortJointInterface</hardwareInterface>
        </joint>
        <actuator name="joint2_to_joint1_motor">
            <mechanicalReduction>1</mechanicalReduction>
            <hardwareInterface>hardware_interface/EffortJointInterface</hardwareInterface>
        </actuator>
    </transmission>
    <transmission name="joint2_trans">
        <type>transmission_interface/SimpleTransmission</type>
        <joint name="joint3_to_joint2">
            <hardwareInterface>hardware_interface/EffortJointInterface</hardwareInterface>
        </joint>
        <actuator name="joint3_to_joint2_motor">
            <mechanicalReduction>1</mechanicalReduction>
            <hardwareInterface>hardware_interface/EffortJointInterface</hardwareInterface>
        </actuator>
    </transmission>
    <transmission name="joint3_trans">
        <type>transmission_interface/SimpleTransmission</type>
        <joint name="joint4_to_joint3">
            <hardwareInterface>hardware_interface/EffortJointInterface</hardwareInterface>
        </joint>
        <actuator name="joint4_to_joint3_motor">
            <mechanicalReduction>1</mechanicalReduction>
            <hardwareInterface>hardware_interface/EffortJointInterface</hardwareInterface>
        </actuator>
    </transmission>
    <transmission name="joint4_trans">
        <type>transmission_interface/SimpleTransmission</type>
        <joint name="joint5_to_joint4">
            <hardwareInterface>hardware_interface/EffortJointInterface</hardwareInterface>
        </joint>
        <actuator name="joint5_to_joint4_motor">
            <mechanicalReduction>1</mechanicalReduction>
            <hardwareInterface>hardware_interface/EffortJointInterface</hardwareInterface>
        </actuator>
    </transmission>
    <transmission name="joint5_trans">
        <type>transmission_interface/SimpleTransmission</type>
        <joint name="joint6_to_joint5">
            <hardwareInterface>hardware_interface/EffortJointInterface</hardwareInterface>
        </joint>
        <actuator name="joint6_to_joint5_motor">
            <mechanicalReduction>1</mechanicalReduction>
            <hardwareInterface>hardware_interface/EffortJointInterface</hardwareInterface>
        </actuator>
    </transmission>
    <transmission name="joint6_trans">
        <type>transmission_interface/SimpleTransmission</type>
        <joint name="joint6output_to_joint6">
            <hardwareInterface>hardware_interface/EffortJointInterface</hardwareInterface>
        </joint>
        <actuator name="joint6output_to_joint6_motor">
            <mechanicalReduction>1</mechanicalReduction>
            <hardwareInterface>hardware_interface/EffortJointInterface</hardwareInterface>
        </actuator>
    </transmission>
    <transmission name="trans_grasping_frame_joint">
        <type>transmission_interface/SimpleTransmission</type>
        <joint name="grasping_frame_joint">
            <hardwareInterface>hardware_interface/EffortJointInterface</hardwareInterface>
        </joint>
        <actuator name="grasping_frame_joint_motor">
            <hardwareInterface>hardware_interface/EffortJointInterface</hardwareInterface>
            <mechanicalReduction>1</mechanicalReduction>
        </actuator>
    </transmission>
    <!-- <xacro:transmission2 link_name="gripper_base" joint_name="gripper_controller"/>
    
    <xacro:transmission2 link_name="gripper_base" joint_name="gripper_base_to_gripper_left2"/>
    
    <xacro:transmission2 link_name="gripper_left3" joint_name="gripper_left3_to_gripper_left1"/>
    
    <xacro:transmission2 link_name="gripper_base" joint_name="gripper_base_to_gripper_right3"/>

    <xacro:transmission2 link_name="gripper_base" joint_name="gripper_base_to_gripper_right2"/>

    <xacro:transmission2 link_name="gripper_right3" joint_name="gripper_right3_to_gripper_right1"/> -->
    <gazebo>
        <plugin filename="libgazebo_ros_control.so" name="gazebo_ros_control">
            <robotNamespace>/</robotNamespace>
            <broadcastTF>false</broadcastTF>
        </plugin>
    </gazebo>
    <link name="joint1">
        <visual>
            <geometry>
                <!--- 0.0 0 -0.04  1.5708 3.14159-->
                <mesh filename="package://limo_description/meshes/joint1.dae" />
            </geometry>
            <origin rpy=" 0 0 -1.5708" xyz="0.0 0 0 " />
        </visual>
        <collision>
            <geometry>
                <!--- 0.0 0 -0.04  1.5708 3.14159-->
                <mesh filename="package://limo_description/meshes/joint1.dae" />
            </geometry>
            <origin rpy=" 0 0 -1.5708" xyz="0.0 0 0 " />
        </collision>
        <inertial>
            <mass value="0.1" />
            <origin rpy="0 0 0" xyz="0 0 0" />
            <inertia ixx="0.03" ixy="0.0" ixz="0.0" iyy="0.03" iyz="0.0" izz="0.03" />
        </inertial>
    </link>
    <link name="joint2">
        <visual>
            <geometry>
                <mesh filename="package://limo_description/meshes/joint2.dae" />
            </geometry>
            <origin rpy=" 0 0 -1.5708" xyz="0.0 0 -0.06096 " />
        </visual>
        <collision>
            <geometry>
                <mesh filename="package://limo_description/meshes/joint2.dae" />
            </geometry>
            <origin rpy=" 0 0 -1.5708" xyz="0.0 0 -0.06096 " />
        </collision>
        <inertial>
            <mass value="0.1" />
            <origin rpy="0 0 0" xyz="0 0 0" />
            <inertia ixx="0.03" ixy="0.0" ixz="0.0" iyy="0.03" iyz="0.0" izz="0.03" />
        </inertial>
    </link>
    <link name="joint3">
        <visual>
            <geometry>
                <mesh filename="package://limo_description/meshes/joint3.dae" />
            </geometry>
            <origin rpy=" 0 -1.5708 0" xyz="0.0 0 0.03256 " />
        </visual>
        <collision>
            <geometry>
                <mesh filename="package://limo_description/meshes/joint3.dae" />
            </geometry>
            <origin rpy=" 0 -1.5708 0" xyz="0.0 0 0.03256 " />
        </collision>
        <inertial>
            <mass value="0.1" />
            <origin rpy="0 0 0" xyz="0 0 0" />
            <inertia ixx="0.03" ixy="0.0" ixz="0.0" iyy="0.03" iyz="0.0" izz="0.03" />
        </inertial>
    </link>
    <link name="joint4">
        <visual>
            <geometry>
                <!--- 0.0 0 -0.04 -->
                <mesh filename="package://limo_description/meshes/joint4.dae" />
            </geometry>
            <origin rpy=" 0 -1.5708 0" xyz="0.0 0 0.03056 " />
        </visual>
        <collision>
            <geometry>
                <!--- 0.0 0 -0.04 -->
                <mesh filename="package://limo_description/meshes/joint4.dae" />
            </geometry>
            <origin rpy=" 0 -1.5708 0" xyz="0.0 0 0.03056 " />
        </collision>
        <inertial>
            <mass value="0.1" />
            <origin rpy="0 0 0" xyz="0 0 0" />
            <inertia ixx="0.03" ixy="0.0" ixz="0.0" iyy="0.03" iyz="0.0" izz="0.03" />
        </inertial>
    </link>
    <link name="joint5">
        <visual>
            <geometry>
                <!--- 0.0 0 -0.04 -->
                <mesh filename="package://limo_description/meshes/joint5.dae" />
            </geometry>
            <origin rpy=" -1.5708 0 0" xyz="0.0 0 -0.03356 " />
        </visual>
        <collision>
            <geometry>
                <!--- 0.0 0 -0.04 -->
                <mesh filename="package://limo_description/meshes/joint5.dae" />
            </geometry>
            <origin rpy=" -1.5708 0 0" xyz="0.0 0 -0.03356 " />
        </collision>
        <inertial>
            <mass value="0.1" />
            <origin rpy="0 0 0" xyz="0 0 0" />
            <inertia ixx="0.03" ixy="0.0" ixz="0.0" iyy="0.03" iyz="0.0" izz="0.03" />
        </inertial>
    </link>
    <link name="joint6">
        <visual>
            <geometry>
                <!--- 0.0 0 -0.04 -->
                <mesh filename="package://limo_description/meshes/joint6.dae" />
            </geometry>
            <origin rpy=" 0 0 0" xyz="0 0.00 -0.038 " />
        </visual>
        <collision>
            <geometry>
                <!--- 0.0 0 -0.04 -->
                <mesh filename="package://limo_description/meshes/joint6.dae" />
            </geometry>
            <origin rpy=" 0 0 0" xyz="0 0.00 -0.038 " />
        </collision>
        <inertial>
            <mass value="0.1" />
            <origin rpy="0 0 0" xyz="0 0 0" />
            <inertia ixx="0.03" ixy="0.0" ixz="0.0" iyy="0.03" iyz="0.0" izz="0.03" />
        </inertial>
    </link>
    <link name="joint6_flange">
        <visual>
            <geometry>
                <!--- 0.0 0 -0.04 -->
                <mesh filename="package://limo_description/meshes/joint7.dae" />
            </geometry>
            <origin rpy=" 0 0 0" xyz="0.0 0 -0.012 " />
        </visual>
        <collision>
            <geometry>
                <!--- 0.0 0 -0.04 -->
                <mesh filename="package://limo_description/meshes/joint7.dae" />
            </geometry>
            <origin rpy=" 0 0 0" xyz="0.0 0 -0.012 " />
        </collision>
        <inertial>
            <mass value="0.1" />
            <origin rpy="0 0 0" xyz="0 0 0" />
            <inertia ixx="0.03" ixy="0.0" ixz="0.0" iyy="0.03" iyz="0.0" izz="0.03" />
        </inertial>
    </link>
    <!-- <link name="gripper_base">
    <visual>
      <geometry>
       <mesh filename="package://limo_description/meshes/gripper_base.dae"/>
      </geometry>
    <origin xyz = "0.0 0 -0.012 " rpy = " 0 0 0"/>
    </visual>
    <collision>
      <geometry>
       <mesh filename="package://limo_description/meshes/gripper_base.dae"/>
      </geometry>
    <origin xyz = "0.0 0 -0.012 " rpy = " 0 0 0"/>
    </collision>
    <inertial>
      <mass value="0.05"/>  
      <inertia ixx="0.001" ixy="0.0" ixz="0.0" iyy="0.001" iyz="0.0" izz="0.001"/>
    </inertial>
  </link>

  <link name="gripper_left1">
    <visual>
      <geometry>
       <mesh filename="package://limo_description/meshes/gripper_left1.dae"/>
      </geometry>
    <origin xyz = "0.039 -0.0133 -0.012 " rpy = " 0 0 0"/>
    </visual>
    <collision>
      <geometry>
       <mesh filename="package://limo_description/meshes/gripper_left1.dae"/>
      </geometry>
        <origin xyz = "0.039 -0.0133 -0.012 " rpy = " 0 0 0"/>
    </collision>
    <inertial>
      <mass value="0.05"/>  
      <inertia ixx="0.001" ixy="0.0" ixz="0.0" iyy="0.001" iyz="0.0" izz="0.001"/>
    </inertial>
  </link>

  <link name="gripper_left2">
    <visual>
      <geometry>
       <mesh filename="package://limo_description/meshes/gripper_left2.dae"/>
      </geometry>
    <origin xyz = "0.005 -0.0195 -0.012 " rpy = " 0 0 0"/>
    </visual>
    <collision>
      <geometry>
       <mesh filename="package://limo_description/meshes/gripper_left2.dae"/>
      </geometry>
        <origin xyz = "0.005 -0.0195 -0.012 " rpy = " 0 0 0"/>
    </collision>
    <inertial>
      <mass value="0.05"/> 
      <inertia ixx="0.001" ixy="0.0" ixz="0.0" iyy="0.001" iyz="0.0" izz="0.001"/>
    </inertial>
  </link>

  <link name="gripper_left3">
    <visual>
      <geometry>
       <mesh filename="package://limo_description/meshes/gripper_left3.dae"/>
      </geometry>
    <origin xyz = "0.012 0.0025 -0.012 " rpy = " 0 0 0"/>
    </visual>
    <collision>
      <geometry>
       <mesh filename="package://limo_description/meshes/gripper_left3.dae"/>
      </geometry>
    <origin xyz = "0.012 0.0025 -0.012 " rpy = " 0 0 0"/>
    </collision>
    <inertial>
      <mass value="0.05"/> 
      <inertia ixx="0.001" ixy="0.0" ixz="0.0" iyy="0.001" iyz="0.0" izz="0.001"/>
    </inertial>
  </link>

  <link name="gripper_right1">
    <visual>
      <geometry>
       <mesh filename="package://limo_description/meshes/gripper_right1.dae"/>
      </geometry>
    <origin xyz = "-0.039 -0.0133 -0.012 " rpy = " 0 0 0"/>
    </visual>
    <collision>
      <geometry>
       <mesh filename="package://limo_description/meshes/gripper_right1.dae"/>
      </geometry>
        <origin xyz = "-0.039 -0.0133 -0.012 " rpy = " 0 0 0"/>
    </collision>
    <inertial>
      <mass value="0.05"/>  
      <inertia ixx="0.001" ixy="0.0" ixz="0.0" iyy="0.001" iyz="0.0" izz="0.001"/>
    </inertial>
  </link>

  <link name="gripper_right2">
    <visual>
      <geometry>
       <mesh filename="package://limo_description/meshes/gripper_right2.dae"/>
      </geometry>
    <origin xyz = "-0.005 -0.0195 -0.012 " rpy = " 0 0 0"/>
    </visual>
    <collision>
      <geometry>
       <mesh filename="package://limo_description/meshes/gripper_right2.dae"/>
      </geometry>
        <origin xyz = "-0.005 -0.0195 -0.012 " rpy = " 0 0 0"/>
    </collision>
    <inertial>
      <mass value="0.05"/>  
      <inertia ixx="0.001" ixy="0.0" ixz="0.0" iyy="0.001" iyz="0.0" izz="0.001"/>
    </inertial>
  </link>

  <link name="gripper_right3">
    <visual>
      <geometry>
       <mesh filename="package://limo_description/meshes/gripper_right3.dae"/>
      </geometry>
    <origin xyz = "-0.012 0.0025 -0.012 " rpy = " 0 0 0"/>
    </visual>
    <collision>
      <geometry>
       <mesh filename="package://limo_description/meshes/gripper_right3.dae"/>
      </geometry>
    <origin xyz = "-0.012 0.0025 -0.012" rpy = " 0 0 0"/>
    </collision>
    <inertial>
      <mass value="0.05"/>  
      <inertia ixx="0.001" ixy="0.0" ixz="0.0" iyy="0.001" iyz="0.0" izz="0.001"/>
    </inertial>
  </link> -->
    <joint name="joint2_to_joint1" type="revolute">
        <axis xyz="0 0 1" />
        <limit effort="1000.0" lower="-3.14" upper="3.14159" velocity="10" />
        <parent link="joint1" />
        <child link="joint2" />
        <origin rpy="0 0 0" xyz="0 0 0.13156" />
    </joint>
    <joint name="joint3_to_joint2" type="revolute">
        <axis xyz="0 0 1" />
        <limit effort="1000.0" lower="-3.14" upper="3.14159" velocity="10" />
        <parent link="joint2" />
        <child link="joint3" />
        <origin rpy="0 1.5708 -1.5708" xyz="0 0  0" />
    </joint>
    <joint name="joint4_to_joint3" type="revolute">
        <axis xyz=" 0 0 1" />
        <limit effort="1000.0" lower="-3.14" upper="3.14159" velocity="10" />
        <parent link="joint3" />
        <child link="joint4" />
        <origin rpy="0 0 0" xyz="  -0.1104 0 0   " />
    </joint>
    <joint name="joint5_to_joint4" type="revolute">
        <axis xyz=" 0 0 1" />
        <limit effort="1000.0" lower="-3.14" upper="3.14159" velocity="10" />
        <parent link="joint4" />
        <child link="joint5" />
        <origin rpy="0 0 -1.5708" xyz="-0.096 0 0.06462" />
    </joint>
    <joint name="joint6_to_joint5" type="revolute">
        <axis xyz="0 0 1" />
        <limit effort="1000.0" lower="-3.14" upper="3.14159" velocity="10" />
        <parent link="joint5" />
        <child link="joint6" />
        <origin rpy="1.5708 -1.5708 0" xyz="0 -0.07318 0" />
    </joint>
    <joint name="joint6output_to_joint6" type="revolute">
        <axis xyz="0 0 1" />
        <limit effort="1000.0" lower="-3.14" upper="3.14159" velocity="10" />
        <parent link="joint6" />
        <child link="joint6_flange" />
        <origin rpy="-1.5708 0 0" xyz="0 0.0456 0" />
    </joint>
    <!-- GRIPPER -->
    <link name="gripper_finger_link1">
        <visual>
            <origin xyz="0.0 0.0 0" />
            <geometry>
                <box size="0.04 0.01 0.01" />
            </geometry>
        </visual>
        <collision>
            <geometry>
                <box size="0.04 0.01 0.01" />
            </geometry>
        </collision>
        <inertial>
            <mass value="0.1" />
            <origin rpy="0 0 0" xyz="0 0 0" />
            <inertia ixx="0.03" ixy="0.0" ixz="0.0" iyy="0.03" iyz="0.0" izz="0.03" />
        </inertial>
    </link>
    <joint name="finger_joint2" type="fixed">
        <parent link="joint6_flange" />
        <child link="gripper_finger_link1" />
        <origin rpy="0.0 1.57 0.0" xyz="-0.02 0 0.02" />
    </joint>
    <link name="gripper_finger_link2">
        <visual>
            <origin xyz="0.0 0.0 0" />
            <geometry>
                <box size="0.04 0.01 0.01" />
            </geometry>
        </visual>
        <collision>
            <geometry>
                <box size="0.04 0.01 0.01" />
            </geometry>
        </collision>
        <inertial>
            <mass value="0.1" />
            <origin rpy="0 0 0" xyz="0 0 0" />
            <inertia ixx="0.03" ixy="0.0" ixz="0.0" iyy="0.03" iyz="0.0" izz="0.03" />
        </inertial>
    </link>
    <joint name="grasping_frame_joint" type="prismatic">
        <parent link="joint6_flange" />
        <child link="gripper_finger_link2" />
        <origin rpy="0.0 1.57 0.0" xyz="0.02 0.0 0.02" />
        <limit effort="1000.0" lower="-0.03" upper="0.0" velocity="10" />
        <axis xyz="0 0 1" />
    </joint>
    <!-- So much collision while working on simulation environment -->
    <!-- <joint name="joint6output_to_gripper_base" type="fixed">
    <parent link="joint6_flange"/>
    <child link="gripper_base"/>
    <origin xyz= "0 0 0.034" rpy = "1.579 0 0"/>  
  </joint>

  <joint name="gripper_controller" type="revolute">
    <axis xyz="0 0 1"/>
    <limit effort = "1000.0" lower = "-0.7" upper = "0.15" velocity = "10"/>
    <parent link="gripper_base"/>
    <child link="gripper_left3"/>
    <origin xyz= "-0.012 0.005 0" rpy = "0 0 0"/> 
  </joint>

  <joint name="gripper_base_to_gripper_left2" type="revolute">
    <axis xyz="0 0 1"/>
    <limit effort = "1000.0" lower = "-0.8" upper = "0.5" velocity = "10"/>
    <parent link="gripper_base"/>
    <child link="gripper_left2"/>
    <origin xyz= "-0.005 0.027 0" rpy = "0 0 0"/> 
    <mimic joint="gripper_controller" multiplier="1.0" offset="0" />
  </joint>

  <joint name="gripper_left3_to_gripper_left1" type="revolute">
    <axis xyz="0 0 1"/>
    <limit effort = "1000.0" lower = "-0.5" upper = "0.5" velocity = "10"/>
    <parent link="gripper_left3"/>
    <child link="gripper_left1"/>
    <origin xyz= "-0.027 0.016 0" rpy = "0 0 0"/> 
    <mimic joint="gripper_controller" multiplier="-1.0" offset="0" />
  </joint>

  <joint name="gripper_base_to_gripper_right3" type="revolute">
    <axis xyz="0 0 1"/>
    <limit effort = "1000.0" lower = "-0.15" upper = "0.7" velocity = "10"/>
    <parent link="gripper_base"/>
    <child link="gripper_right3"/>
    <origin xyz= "0.012 0.005 0" rpy = "0 0 0"/> 
    <mimic joint="gripper_controller" multiplier="-1.0" offset="0" />
  </joint>

  <joint name="gripper_base_to_gripper_right2" type="revolute">
    <axis xyz="0 0 1"/>
    <limit effort = "1000.0" lower = "-0.5" upper = "0.8" velocity = "10"/>
    <parent link="gripper_base"/>
    <child link="gripper_right2"/>
    <origin xyz= "0.005 0.027 0" rpy = "0 0 0"/> 
    <mimic joint="gripper_controller" multiplier="-1.0" offset="0" />
  </joint>

  <joint name="gripper_right3_to_gripper_right1" type="revolute">
    <axis xyz="0 0 1"/>
    <limit effort = "1000.0" lower = "-0.5" upper = "0.5" velocity = "10"/>
    <parent link="gripper_right3"/>
    <child link="gripper_right1"/>
    <origin xyz= "0.027 0.016 0" rpy = "0 0 0"/> 
    <mimic joint="gripper_controller" multiplier="1.0" offset="0" />
  </joint> -->
    <gazebo reference="laser_link">
        <sensor name="laser_sensor" type="ray">
            <pose>0 0 0 0 0 0</pose>
            <visualize>false</visualize>
            <update_rate>8</update_rate>
            <ray>
                <scan>
                    <horizontal>
                        <samples>720</samples>
                        <resolution>1</resolution>
                        <min_angle>-2.09439504</min_angle>
                        <max_angle>2.09439504</max_angle>
                    </horizontal>
                </scan>
                <range>
                    <min>0.05</min>
                    <max>8.0</max>
                    <resolution>0.01</resolution>
                </range>
                <noise>
                    <type>gaussian</type>
                    <mean>0.0</mean>
                    <stddev>0.01</stddev>
                </noise>
            </ray>
            <plugin filename="libgazebo_ros_laser.so" name="gazebo_ros_laser_sensor">
                <topicName>/limo/scan</topicName>
                <frameName>laser_link</frameName>
            </plugin>
        </sensor>
    </gazebo>
    <gazebo reference="depth_camera_link">
        <sensor name="sensor_camera" type="depth">
            <pose>0.0 0.0 0.0 0.0 0.0 0.0</pose>
            <always_on>true</always_on>
            <visualize>true</visualize>
            <update_rate>10.0</update_rate>
            <camera name="head">
                <horizontal_fov>1.3962634</horizontal_fov>
                <image>
                    <width>640</width>
                    <height>480</height>
                    <format>R8G8B8</format>
                </image>
                <clip>
                    <near>0.02</near>
                    <far>300</far>
                </clip>
            </camera>
            <plugin filename="libgazebo_ros_openni_kinect.so" name="gazebo_ros_depth_camera_sensor">
                <baseline>0.2</baseline>
                <alwaysOn>true</alwaysOn>
                <!-- Keep this zero, update_rate in the parent <sensor> tag
                will control the frame rate. -->
                <updateRate>0.0</updateRate>
                <cameraName>camera_ir</cameraName>
                <imageTopicName>/limo/color/image_raw</imageTopicName>
                <cameraInfoTopicName>/limo/color/camera_info</cameraInfoTopicName>
                <depthImageTopicName>/limo/depth/image_raw</depthImageTopicName>
                <depthImageCameraInfoTopicName>/limo/depth/camera_info</depthImageCameraInfoTopicName>
                <pointCloudTopicName>/limo/depth/points</pointCloudTopicName>
                <frameName>depth_link</frameName>
                <cameraname>depth_camera_link</cameraname>
                <pointCloudCutoff>0.5</pointCloudCutoff>
                <pointCloudCutoffMax>3.0</pointCloudCutoffMax>
                <distortionK1>0</distortionK1>
                <distortionK2>0</distortionK2>
                <distortionK3>0</distortionK3>
                <distortionT1>0</distortionT1>
                <distortionT2>0</distortionT2>
                <CxPrime>0</CxPrime>
                <Cx>0</Cx>
                <Cy>0</Cy>
                <focalLength>0</focalLength>
                <hackBaseline>0</hackBaseline>
            </plugin>
        </sensor>
    </gazebo>
    <gazebo reference="imu_link">
        <gravity>true</gravity>
        <sensor name="imu_sensor" type="imu">
            <always_on>true</always_on>
            <update_rate>100</update_rate>
            <visualize>true</visualize>
            <topic>__default_topic__</topic>
            <plugin filename="libgazebo_ros_imu_sensor.so" name="imu_plugin">
                <topicName>/limo/imu</topicName>
                <bodyName>imu_link</bodyName>
                <updateRateHZ>100.0</updateRateHZ>
                <gaussianNoise>0.001</gaussianNoise>
                <xyzOffset>0 0 0</xyzOffset>
                <rpyOffset>0 0 0</rpyOffset>
                <frameName>imu_link</frameName>
            </plugin>
            <pose>0 0 0 0 0 0</pose>
        </sensor>
    </gazebo>
    <gazebo reference="front_left_wheel">
        <mu1>10</mu1>
        <mu2>10</mu2>
        <kp>10000000.0</kp>
        <kd>1.0</kd>
        <minDepth>0.01</minDepth>
        <fdir1>1 0 0</fdir1>
        <maxContacts value="64" />
    </gazebo>
    <gazebo reference="front_right_wheel">
        <mu1>10</mu1>
        <mu2>10</mu2>
        <kp>10000000.0</kp>
        <kd>1.0</kd>
        <minDepth>0.01</minDepth>
        <fdir1>1 0 0</fdir1>
        <maxContacts value="64" />
    </gazebo>
    <gazebo reference="rear_left_wheel">
        <mu1>10</mu1>
        <mu2>10</mu2>
        <kp>10000000.0</kp>
        <kd>1.0</kd>
        <minDepth>0.01</minDepth>
        <fdir1>1 0 0</fdir1>
        <maxContacts value="64" />
    </gazebo>
    <gazebo reference="rear_right_wheel">
        <mu1>10</mu1>
        <mu2>10</mu2>
        <kp>10000000.0</kp>
        <kd>1.0</kd>
        <minDepth>0.01</minDepth>
        <fdir1>1 0 0</fdir1>
        <maxContacts value="64" />
    </gazebo>
    <gazebo>
        <plugin filename="libgazebo_ros_skid_steer_drive.so" name="four_diff_controller">
            <updateRate>100.0</updateRate>
            <robotNamespace />
            <leftFrontJoint>front_left_wheel</leftFrontJoint>
            <rightFrontJoint>front_right_wheel</rightFrontJoint>
            <leftRearJoint>rear_left_wheel</leftRearJoint>
            <rightRearJoint>rear_right_wheel</rightRearJoint>
            <wheelSeparation>0.172</wheelSeparation>
            <wheelDiameter>0.09</wheelDiameter>
            <robotBaseFrame>base_footprint</robotBaseFrame>
            <commandTopic>cmd_vel</commandTopic>
            <torque>50</torque>
            <broadcastTF>false</broadcastTF>
            <odometryTopic>odom</odometryTopic>
            <odometryFrame>odom</odometryFrame>
            <covariance_x>0.000100</covariance_x>
            <covariance_y>0.000100</covariance_y>
            <covariance_yaw>0.010000</covariance_yaw>
        </plugin>
    </gazebo>
    <link name="base_footprint" />
    <joint name="base_joint" type="fixed">
        <parent link="base_footprint" />
        <child link="base_link" />
        <origin rpy="0 0 0" xyz="0.0 0.0 0.15" />
    </joint>
    <!-- Base link -->
    <link name="base_link">
        <visual>
            <origin rpy="0 0 1.57" xyz="0 0 -0.15" />
            <geometry>
                <mesh filename="package://limo_description/meshes/limo_base.dae" scale="1 1 1" />
            </geometry>
        </visual>
        <collision>
            <!--origin xyz="0 0 -0.15" rpy="0 0 1.57" /-->
            <origin rpy="0 0 0" xyz="0 0 0" />
            <geometry>
                <box size="0.13 0.12 0.1" />
            </geometry>
        </collision>
        <inertial>
            <mass value="0.1" />
            <origin xyz="0 0 0" rpy="0 0 0" />
            <inertia ixx="0.03" iyy="0.03" izz="0.03" ixy="0.0" ixz="0.0" iyz="0.0" />
        </inertial>
    </link>
    <link name="inertial_link">
        <inertial>
            <origin xyz="0.0 0.0 0.0" />
            <mass value="2.1557" />
            <inertia ixx="0.24" ixy="0" ixz="0" iyy="0.96" iyz="0" izz="0.96" />
        </inertial>
    </link>
    <joint name="inertial_joint" type="fixed">
        <origin rpy="0 0 0" xyz="0 0 0" />
        <parent link="base_link" />
        <child link="inertial_link" />
    </joint>
    <link name="laser_link">
        <pose>0 0 0 0 0 0</pose>
        <inertial>
            <mass value="0.1" />
            <origin rpy="0 0 0" xyz="0.0 0 0" />
            <inertia ixx="1e-6" ixy="0" ixz="0" iyy="1e-6" iyz="0" izz="1e-6" />
        </inertial>
        <visual name="laser_visual">
            <origin rpy="0 0 0" xyz="0 0 0" />
            <geometry>
                <cylinder length="0.01" radius="0.02" />
            </geometry>
            <material name="laser_material">
                <ambient>0.1 0.1 0.1 1</ambient>
                <diffuse>0.1 0.1 0.2 1</diffuse>
                <specular>0 0 0 0</specular>
                <emissive>0 0 0 1</emissive>
            </material>
        </visual>
        <collision name="laser_collision">
            <origin rpy="0 0 0" xyz="0 0 0" />
            <geometry>
                <cylinder length="0.016" radius="0.032" />
            </geometry>
        </collision>
    </link>
    <joint name="laser_joint" type="fixed">
        <origin rpy="0 0 0" xyz="0.103 0 -0.034" />
        <child link="laser_link" />
        <parent link="base_link" />
    </joint>
    <gazebo reference="laser_link">
        <material>Gazebo/Yellow</material>
    </gazebo>
    <link name="depth_camera_link">
        <pose>0 0 0 0 0 0</pose>
        <inertial>
            <mass value="0.1" />
            <origin rpy="0 0 0" xyz="0.0 0 0" />
            <inertia ixx="1e-6" ixy="0" ixz="0" iyy="1e-6" iyz="0" izz="1e-6" />
        </inertial>
        <visual name="depth_camera_visual">
            <origin rpy="0 0 0" xyz="0 0 0" />
            <geometry>
                <box size="0.02 0.06 0.015" />
            </geometry>
            <material name="depth_camera_material">
                <ambient>0.1 0.1 0.1 1</ambient>
                <diffuse>0.1 0.1 0.2 1</diffuse>
                <specular>0 0 0 0</specular>
                <emissive>0 0 0 1</emissive>
            </material>
        </visual>
        <collision name="depth_camera_collision">
            <origin rpy="0 0 0" xyz="0 0 0" />
            <geometry>
                <box size="0.02 0.06 0.015" />
            </geometry>
        </collision>
    </link>
    <joint name="depth_camera_joint" type="fixed">
        <origin rpy="0 0 0" xyz="0.084 0 0.03" />
        <child link="depth_camera_link" />
        <parent link="base_link" />
    </joint>
    <link name="depth_link" />
    <joint name="depth_camera_to_camera_joint" type="fixed">
        <origin rpy="-1.570795 0 -1.570795 " xyz="0 0 0" />
        <parent link="depth_camera_link" />
        <child link="depth_link" />
    </joint>
    <gazebo reference="depth_camera_link">
        <material>Gazebo/Yellow</material>
    </gazebo>
    <link name="imu_link">
        <pose>0 0 0 0 0 0</pose>
        <inertial>
            <mass value="0.01" />
            <origin rpy="0 0 0" xyz="0.0 0 0" />
            <inertia ixx="1e-7" ixy="0" ixz="0" iyy="1e-7" iyz="0" izz="1e-7" />
        </inertial>
        <visual name="imu_visual">
            <origin rpy="0 0 0" xyz="0 0 0" />
            <geometry>
                <box size="0.001 0.001 0.001" />
            </geometry>
            <material name="imu_material">
                <ambient>0.1 0.1 0.1 1</ambient>
                <diffuse>0.1 0.1 0.2 1</diffuse>
                <specular>0 0 0 0</specular>
                <emissive>0 0 0 1</emissive>
            </material>
        </visual>
        <collision name="imu_collision">
            <origin rpy="0 0 0" xyz="0 0 0" />
            <geometry>
                <box size="0.001 0.001 0.001" />
            </geometry>
        </collision>
    </link>
    <joint name="imu_joint" type="fixed">
        <origin rpy="0 0 0" xyz="0.0 0 -0.1" />
        <child link="imu_link" />
        <parent link="base_link" />
    </joint>
    <gazebo reference="imu_link">
        <material>Gazebo/Yellow</material>
    </gazebo>
    <link name="front_left_wheel_link">
        <inertial>
            <origin xyz="0 0 0" rpy="0 0 0" />
            <mass value="0.5" />
            <inertia ixx="0.01055" ixy="0" ixz="0" iyy="0.00075" iyz="0" izz="0.01055" />
        </inertial>
        <visual>
            <origin rpy="0 0 0" xyz="0 0 0" />
            <geometry>
                <mesh filename="package://limo_description/meshes/limo_wheel.dae" />
            </geometry>
        </visual>
        <collision>
            <origin rpy="1.57 0 0" xyz="0 0.0225 0" />
            <geometry>
                <cylinder length="0.045" radius="0.045" />
            </geometry>
        </collision>
    </link>
    <joint name="front_left_wheel" type="continuous">
        <parent link="base_link" />
        <child link="front_left_wheel_link" />
        <origin rpy="0 0  0" xyz="0.1 0.065 -0.1" />
        <axis xyz="0 1 0" />
    </joint>
    <link name="front_right_wheel_link">
        <inertial>
            <origin xyz="0 0 0" rpy="0 0 0" />
            <mass value="0.5" />
            <inertia ixx="0.01055" ixy="0" ixz="0" iyy="0.00075" iyz="0" izz="0.01055" />
        </inertial>
        <visual>
            <origin rpy="0 0 0" xyz="0 0 0" />
            <geometry>
                <mesh filename="package://limo_description/meshes/limo_wheel.dae" />
            </geometry>
        </visual>
        <collision>
            <origin rpy="1.57 0 0" xyz="0 0.0225 0" />
            <geometry>
                <cylinder length="0.045" radius="0.045" />
            </geometry>
        </collision>
    </link>
    <joint name="front_right_wheel" type="continuous">
        <parent link="base_link" />
        <child link="front_right_wheel_link" />
        <origin rpy="3.14159 0 0" xyz="0.1 -0.065 -0.1" />
        <axis xyz="0 -1 0" />
    </joint>
    <link name="rear_left_wheel_link">
        <inertial>
            <origin xyz="0 0 0" rpy="0 0 0" />
            <mass value="0.5" />
            <inertia ixx="0.01055" ixy="0" ixz="0" iyy="0.00075" iyz="0" izz="0.01055" />
        </inertial>
        <visual>
            <origin rpy="0 0 0" xyz="0 0 0" />
            <geometry>
                <mesh filename="package://limo_description/meshes/limo_wheel.dae" />
            </geometry>
        </visual>
        <collision>
            <origin rpy="1.57 0 0" xyz="0 0.0225 0" />
            <geometry>
                <cylinder length="0.045" radius="0.045" />
            </geometry>
        </collision>
    </link>
    <joint name="rear_left_wheel" type="continuous">
        <parent link="base_link" />
        <child link="rear_left_wheel_link" />
        <origin rpy="0 0 0" xyz="-0.1 0.065 -0.1" />
        <axis xyz="0 1 0" />
    </joint>
    <link name="rear_right_wheel_link">
        <inertial>
            <origin xyz="0 0 0" rpy="0 0 0" />
            <mass value="0.5" />
            <inertia ixx="0.01055" ixy="0" ixz="0" iyy="0.00075" iyz="0" izz="0.01055" />
        </inertial>
        <visual>
            <origin rpy="0 0 0" xyz="0 0 0" />
            <geometry>
                <mesh filename="package://limo_description/meshes/limo_wheel.dae" />
            </geometry>
        </visual>
        <collision>
            <origin rpy="1.57 0 0" xyz="0 0.0225 0" />
            <geometry>
                <cylinder length="0.045" radius="0.045" />
            </geometry>
        </collision>
    </link>
    <joint name="rear_right_wheel" type="continuous">
        <parent link="base_link" />
        <child link="rear_right_wheel_link" />
        <origin rpy="3.14159 0 0" xyz="-0.1 -0.065 -0.1" />
        <axis xyz="0 -1 0" />
    </joint>
    <!-- <xacro:include filename="$(find limo_description)/urdf/arm_transmission.gazebo"/> -->
    <joint name="limo_mycobot" type="fixed">
        <origin rpy="0 0 0" xyz="-0.02 0.0 0.0" />
        <parent link="base_link" />
        <child link="joint1" />
    </joint>
    <transmission name="trans_front_left_wheel">
        <type>transmission_interface/SimpleTransmission</type>
        <joint name="front_left_wheel">
            <hardwareInterface>hardware_interface/EffortJointInterface</hardwareInterface>
        </joint>
        <actuator name="front_left_wheel_motor">
            <hardwareInterface>hardware_interface/EffortJointInterface</hardwareInterface>
            <mechanicalReduction>1</mechanicalReduction>
        </actuator>
    </transmission>
    <transmission name="trans_front_right_wheel">
        <type>transmission_interface/SimpleTransmission</type>
        <joint name="front_right_wheel">
            <hardwareInterface>hardware_interface/EffortJointInterface</hardwareInterface>
        </joint>
        <actuator name="front_right_wheel_motor">
            <hardwareInterface>hardware_interface/EffortJointInterface</hardwareInterface>
            <mechanicalReduction>1</mechanicalReduction>
        </actuator>
    </transmission>
    <transmission name="trans_rear_left_wheel">
        <type>transmission_interface/SimpleTransmission</type>
        <joint name="rear_left_wheel">
            <hardwareInterface>hardware_interface/EffortJointInterface</hardwareInterface>
        </joint>
        <actuator name="rear_left_wheel_motor">
            <hardwareInterface>hardware_interface/EffortJointInterface</hardwareInterface>
            <mechanicalReduction>1</mechanicalReduction>
        </actuator>
    </transmission>
    <transmission name="trans_rear_right_wheel">
        <type>transmission_interface/SimpleTransmission</type>
        <joint name="rear_right_wheel">
            <hardwareInterface>hardware_interface/EffortJointInterface</hardwareInterface>
        </joint>
        <actuator name="rear_right_wheel_motor">
            <hardwareInterface>hardware_interface/EffortJointInterface</hardwareInterface>
            <mechanicalReduction>1</mechanicalReduction>
        </actuator>
    </transmission>
</robot>

